Workbook

Sheet 在此导入
A1: 第一步：将你导出的一图流物品价值表Excel中的内容全部复制，覆盖粘贴到此处
A2: 物品id | B2: 物品名称 | C2: 等效理智 | D2: 物品稀有度 | F2: 第二步：填写符合你价值观的基建产物比例（默认为理智算法）
A3: 30145 | B3: 晶体电子单元 | C3: 243.31303 | D3: 5 | F3: 经验书：赤金：订单
A4: 30155 | B4: 烧结核凝晶 | C4: 258.88599 | D4: 5 | F4: 经验书 | G4: 1
A5: 30115 | B5: 聚合剂 | C5: 211.21262 | D5: 5 | F5: 赤金 | G5: 0.8
A6: 30135 | B6: D32钢 | C6: 121.54504 | D6: 5 | F6: 订单 | G6: =733/2990 -> 0.2451505
A7: 30125 | B7: 双极纳米片 | C7: 93.282046 | D7: 5
A8: 30165 | B8: 重相位对映体 | C8: 304.11023 | D8: 5 | F8: 第三步：看结论
A9: 31094 | B9: 手性屈光体 | C9: 74.234875 | D9: 4 | F9: 由于当前回收站机制尚不完全明晰，现假设两种可能的机制
A10: 31104 | B10: 液化醚吸聚体 | C10: 66.228899 | D10: 4
A11: 31114 | B11: 聚能动力单元 | C11: 84.970473 | D11: 4 | F11: 假设1：额外池和普通池各产一次材料
A12: 30044 | B12: 异铁块 | C12: 95.513345 | D12: 4 | F12: 在你的定义下，回收站每100%效率每天的理智产出为 | K12: =计算表!C49 -> 11.97296 | L12: 理智
A13: 31084 | B13: 环烃预制体 | C13: 87.081846 | D13: 4 | F13: 此时精0旅骨（20%）等价于 | I13: =计算表!F53 -> 0.08689962 | J13: 制造站效率
A14: 30054 | B14: 酮阵列 | C14: 65.802333 | D14: 4 | F14: 精二旅骨（30%）等价于 | I14: =计算表!C53 -> 0.13034943 | J14: 制造站效率
A15: 30064 | B15: 改量装置 | C15: 63.342877 | D15: 4
A16: 30104 | B16: RMA70-24 | C16: 55.702369 | D16: 4 | F16: 假设2：额外池材料会顶替普通池材料
A17: 30094 | B17: 五水研磨石 | C17: 55.044825 | D17: 4 | F17: 在你的定义下，回收站每100%效率每天的理智产出为 | K17: ='计算表 (2)'!C49 -> 11.374513 | L17: 理智
A18: 31074 | B18: 固化纤维板 | C18: 79.78212 | D18: 4 | F18: 此时精0旅骨（20%）等价于 | I18: ='计算表 (2)'!F53 -> 0.082556096 | J18: 制造站效率
A19: 30024 | B19: 糖聚块 | C19: 61.049845 | D19: 4 | F19: 精二旅骨（30%）等价于 | I19: ='计算表 (2)'!C53 -> 0.12383414 | J19: 制造站效率
A20: 31034 | B20: 晶体电路 | C20: 76.005608 | D20: 4
A21: 31024 | B21: 炽合金块 | C21: 53.480204 | D21: 4
A22: 31044 | B22: 精炼溶剂 | C22: 74.158288 | D22: 4
A23: 31054 | B23: 切削原液 | C23: 49.683406 | D23: 4
A24: 31064 | B24: 转质盐聚块 | C24: 72.109489 | D24: 4
A25: 31014 | B25: 聚合凝胶 | C25: 62.525351 | D25: 4
A26: 30084 | B26: 三水锰矿 | C26: 22.021326 | D26: 4
A27: 30034 | B27: 聚酸酯块 | C27: 60.689845 | D27: 4
A28: 30014 | B28: 提纯源岩 | C28: 61.120421 | D28: 4
A29: 30074 | B29: 白马醇 | C29: 20.581326 | D29: 4
A30: 31083 | B30: 环烃聚质 | C30: 31.87648 | D30: 3
A31: 31093 | B31: 类凝结核 | C31: 26.45707 | D31: 3
... A149: recruitment10 | B149: 新年寻访凭证 | C149: 0 | D149: 5

Sheet 计算表
A1: 回收站池子1权重 | L1: 回收站池子2权重
A2: 绿材料 | B2: 材料名 | C2: 理智价值 | D2: 权重 | E2: 理智 | F2: 积分 | G2: 期望积分 | H2: 池子2摸奖次数 | I2: 池子2摸奖理智 | J2: 总理智 | M2: 材料名 | N2: 理智价值 | O2: 权重 | P2: 理智
B3: 装置 | C3: =在此导入!C51 -> 8.142283 | D3: 717 | E3: =C3*D3/10000 -> 0.58380169 | F3: 650 | G3: =D3*F3/10000 -> 46.605 | H3: =G3/10000 -> 0.0046605 | I3: =H3*$P$30 -> 0.36529039 | J3: =E3+I3 -> 0.94909208 | L3: 单独2种紫材料 | M3: 聚酸酯块 | N3: =C9 -> 60.689845 | O3: 40 | P3: =N3*O3/10000 -> 0.24275938
B4: 酮凝集 | C4: =在此导入!C52 -> 6.142156 | D4: 717 | E4: =C4*D4/10000 -> 0.44039259 | F4: 650 | G4: =D4*F4/10000 -> 46.605 | H4: =G4/10000 -> 0.0046605 | I4: =H4*$P$30 -> 0.36529039 | J4: =E4+I4 -> 0.80568297 | M4: 糖聚块 | N4: =C10 -> 61.049845 | O4: 40 | P4: =N4*O4/10000 -> 0.24419938
B5: 异铁 | C5: =在此导入!C53 -> 6.142156 | D5: 717 | E5: =C5*D5/10000 -> 0.44039259 | F5: 650 | G5: =D5*F5/10000 -> 46.605 | H5: =G5/10000 -> 0.0046605 | I5: =H5*$P$30 -> 0.36529039 | J5: =E5+I5 -> 0.80568297 | L5: 单独紫土 | M5: 提纯源岩 | N5: =C28 -> 61.120421 | O5: 488 | P5: =N5*O5/10000 -> 2.9826765
B6: 聚酸酯 | C6: =在此导入!C54 -> 4.954034 | D6: 717 | E6: =C6*D6/10000 -> 0.35520424 | F6: 650 | G6: =D6*F6/10000 -> 46.605 | H6: =G6/10000 -> 0.0046605 | I6: =H6*$P$30 -> 0.36529039 | J6: =E6+I6 -> 0.72049462 | L6: 其余紫材料 | M6: 手性屈光体 | N6: =C29 -> 74.234875 | O6: 468 | P6: =N6*O6/10000 -> 3.4741921
B7: 糖 | C7: =在此导入!C55 -> 4.954034 | D7: 717 | E7: =C7*D7/10000 -> 0.35520424 | F7: 650 | G7: =D7*F7/10000 -> 46.605 | H7: =G7/10000 -> 0.0046605 | I7: =H7*$P$30 -> 0.36529039 | J7: =E7+I7 -> 0.72049462 | M7: 液化醚吸聚体 | N7: =C30 -> 66.228899 | O7: 468 | P7: =N7*O7/10000 -> 3.0995125
B8: 固源岩 | C8: =在此导入!C56 -> 3.35648 | D8: 717 | E8: =C8*D8/10000 -> 0.24065962 | F8: 650 | G8: =D8*F8/10000 -> 46.605 | H8: =G8/10000 -> 0.0046605 | I8: =H8*$P$30 -> 0.36529039 | J8: =E8+I8 -> 0.60595 | M8: 聚能动力单元 | N8: =C31 -> 84.970473 | O8: 468 | P8: =N8*O8/10000 -> 3.9766181
A9: 单独2种紫材料 | B9: 聚酸酯块 | C9: =在此导入!C27 -> 60.689845 | D9: 4 | E9: =C9*D9/10000 -> 0.024275938 | F9: 0 | G9: =D9*F9/10000 -> 0 | H9: =G9/10000 -> 0 | I9: =H9*$P$30 -> 0 | J9: =E9+I9 -> 0.024275938 | M9: 异铁块 | N9: =C32 -> 95.513345 | O9: 468 | P9: =N9*O9/10000 -> 4.4700245
B10: 糖聚块 | C10: =在此导入!C19 -> 61.049845 | D10: 4 | E10: =C10*D10/10000 -> 0.024419938 | F10: 0 | G10: =D10*F10/10000 -> 0 | H10: =G10/10000 -> 0 | I10: =H10*$P$30 -> 0 | J10: =E10+I10 -> 0.024419938 | M10: 环烃预制体 | N10: =C33 -> 87.081846 | O10: 468 | P10: =N10*O10/10000 -> 4.0754304
A11: 蓝材料(不含4中坚) | B11: 环烃聚质 | C11: =在此导入!C30 -> 31.87648 | D11: 290 | E11: =C11*D11/10000 -> 0.92441791 | F11: 500 | G11: =D11*F11/10000 -> 14.5 | H11: =G11/10000 -> 0.00145 | I11: =H11*$P$30 -> 0.11365112 | J11: =E11+I11 -> 1.038069 | M11: 酮阵列 | N11: =C34 -> 65.802333 | O11: 468 | P11: =N11*O11/10000 -> 3.0795492
B12: 类凝结核 | C12: =在此导入!C31 -> 26.45707 | D12: 290 | E12: =C12*D12/10000 -> 0.76725502 | F12: 500 | G12: =D12*F12/10000 -> 14.5 | H12: =G12/10000 -> 0.00145 | I12: =H12*$P$30 -> 0.11365112 | J12: =E12+I12 -> 0.88090614 | M12: 改量装置 | N12: =C35 -> 63.342877 | O12: 468 | P12: =N12*O12/10000 -> 2.9644466
B13: 液化高能气体 | C13: =在此导入!C32 -> 29.772152 | D13: 290 | E13: =C13*D13/10000 -> 0.86339241 | F13: 500 | G13: =D13*F13/10000 -> 14.5 | H13: =G13/10000 -> 0.00145 | I13: =H13*$P$30 -> 0.11365112 | J13: =E13+I13 -> 0.97704353 | M13: RMA70-24 | N13: =C36 -> 55.702369 | O13: 468 | P13: =N13*O13/10000 -> 2.6068709
B14: 电极单元 | C14: =在此导入!C33 -> 26.544 | D14: 290 | E14: =C14*D14/10000 -> 0.769776 | F14: 500 | G14: =D14*F14/10000 -> 14.5 | H14: =G14/10000 -> 0.00145 | I14: =H14*$P$30 -> 0.11365112 | J14: =E14+I14 -> 0.88342712 | M14: 五水研磨石 | N14: =C37 -> 55.044825 | O14: 468 | P14: =N14*O14/10000 -> 2.5760978
B15: 全新装置 | C15: =在此导入!C34 -> 31.871012 | D15: 290 | E15: =C15*D15/10000 -> 0.92425935 | F15: 500 | G15: =D15*F15/10000 -> 14.5 | H15: =G15/10000 -> 0.00145 | I15: =H15*$P$30 -> 0.11365112 | J15: =E15+I15 -> 1.0379105 | M15: 固化纤维板 | N15: =C38 -> 79.78212 | O15: 468 | P15: =N15*O15/10000 -> 3.7338032
B16: 褐素纤维 | C16: =在此导入!C36 -> 28.6785 | D16: 290 | E16: =C16*D16/10000 -> 0.83167649 | F16: 500 | G16: =D16*F16/10000 -> 14.5 | H16: =G16/10000 -> 0.00145 | I16: =H16*$P$30 -> 0.11365112 | J16: =E16+I16 -> 0.94532762 | M16: 晶体电路 | N16: =C39 -> 76.005608 | O16: 468 | P16: =N16*O16/10000 -> 3.5570624
B17: 转质盐组 | C17: =在此导入!C37 -> 29.743557 | D17: 290 | E17: =C17*D17/10000 -> 0.86256315 | F17: 500 | G17: =D17*F17/10000 -> 14.5 | H17: =G17/10000 -> 0.00145 | I17: =H17*$P$30 -> 0.11365112 | J17: =E17+I17 -> 0.97621427 | M17: 炽合金块 | N17: =C40 -> 53.480204 | O17: 468 | P17: =N17*O17/10000 -> 2.5028735
B18: 化合切削液 | C18: =在此导入!C39 -> 26.453303 | D18: 290 | E18: =C18*D18/10000 -> 0.76714579 | F18: 500 | G18: =D18*F18/10000 -> 14.5 | H18: =G18/10000 -> 0.00145 | I18: =H18*$P$30 -> 0.11365112 | J18: =E18+I18 -> 0.88079691 | M18: 精炼溶剂 | N18: =C41 -> 74.158288 | O18: 468 | P18: =N18*O18/10000 -> 3.4706079
B19: 凝胶 | C19: =在此导入!C40 -> 24.45707 | D19: 290 | E19: =C19*D19/10000 -> 0.70925502 | F19: 500 | G19: =D19*F19/10000 -> 14.5 | H19: =G19/10000 -> 0.00145 | I19: =H19*$P$30 -> 0.11365112 | J19: =E19+I19 -> 0.82290614 | M19: 切削原液 | N19: =C42 -> 49.683406 | O19: 468 | P19: =N19*O19/10000 -> 2.3251834
B20: 半自然溶剂 | C20: =在此导入!C41 -> 26.464606 | D20: 290 | E20: =C20*D20/10000 -> 0.76747358 | F20: 500 | G20: =D20*F20/10000 -> 14.5 | H20: =G20/10000 -> 0.00145 | I20: =H20*$P$30 -> 0.11365112 | J20: =E20+I20 -> 0.8811247 | M20: 转质盐聚块 | N20: =C43 -> 72.109489 | O20: 468 | P20: =N20*O20/10000 -> 3.3747241
B21: 酮凝集组 | C21: =在此导入!C43 -> 23.870504 | D21: 290 | E21: =C21*D21/10000 -> 0.6922446 | F21: 500 | G21: =D21*F21/10000 -> 14.5 | H21: =G21/10000 -> 0.00145 | I21: =H21*$P$30 -> 0.11365112 | J21: =E21+I21 -> 0.80589573 | M21: 聚合凝胶 | N21: =C44 -> 62.525351 | O21: 468 | P21: =N21*O21/10000 -> 2.9261864
B22: 异铁组 | C22: =在此导入!C44 -> 23.870504 | D22: 290 | E22: =C22*D22/10000 -> 0.6922446 | F22: 500 | G22: =D22*F22/10000 -> 14.5 | H22: =G22/10000 -> 0.00145 | I22: =H22*$P$30 -> 0.11365112 | J22: =E22+I22 -> 0.80589573 | M22: 三水锰矿 | N22: =C45 -> 22.021326 | O22: 468 | P22: =N22*O22/10000 -> 1.030598
B23: 炽合金 | C23: =在此导入!C46 -> 22.305882 | D23: 290 | E23: =C23*D23/10000 -> 0.64687059 | F23: 500 | G23: =D23*F23/10000 -> 14.5 | H23: =G23/10000 -> 0.00145 | I23: =H23*$P$30 -> 0.11365112 | J23: =E23+I23 -> 0.76052171 | M23: 白马醇 | N23: =C46 -> 20.581326 | O23: 468 | P23: =N23*O23/10000 -> 0.96320604
B24: 聚酸酯组 | C24: =在此导入!C47 -> 19.118016 | D24: 290 | E24: =C24*D24/10000 -> 0.55442247 | F24: 500 | G24: =D24*F24/10000 -> 14.5 | H24: =G24/10000 -> 0.00145 | I24: =H24*$P$30 -> 0.11365112 | J24: =E24+I24 -> 0.66807359 | L24: 金材料 | M24: 晶体电子单元 | N24: =在此导入!C3 -> 243.31303 | O24: 168 | P24: =N24*O24/10000 -> 4.0876589
B25: 糖组 | C25: =在此导入!C48 -> 19.118016 | D25: 290 | E25: =C25*D25/10000 -> 0.55442247 | F25: 500 | G25: =D25*F25/10000 -> 14.5 | H25: =G25/10000 -> 0.00145 | I25: =H25*$P$30 -> 0.11365112 | J25: =E25+I25 -> 0.66807359 | M25: 烧结核凝晶 | N25: =在此导入!C4 -> 258.88599 | O25: 168 | P25: =N25*O25/10000 -> 4.3492846
B26: 晶体元件 | C26: =在此导入!C49 -> 23.666794 | D26: 290 | E26: =C26*D26/10000 -> 0.68633703 | F26: 500 | G26: =D26*F26/10000 -> 14.5 | H26: =G26/10000 -> 0.00145 | I26: =H26*$P$30 -> 0.11365112 | J26: =E26+I26 -> 0.79998815 | M26: 聚合剂 | N26: =在此导入!C5 -> 211.21262 | O26: 168 | P26: =N26*O26/10000 -> 3.548372
B27: 固源岩组 | C27: =在此导入!C50 -> 16.084278 | D27: 290 | E27: =C27*D27/10000 -> 0.46644406 | F27: 500 | G27: =D27*F27/10000 -> 14.5 | H27: =G27/10000 -> 0.00145 | I27: =H27*$P$30 -> 0.11365112 | J27: =E27+I27 -> 0.58009518 | M27: D32钢 | N27: =在此导入!C6 -> 121.54504 | O27: 168 | P27: =N27*O27/10000 -> 2.0419566
A28: 其余紫材料 | B28: 提纯源岩 | C28: =在此导入!C28 -> 61.120421 | D28: 40 | E28: =C28*D28/10000 -> 0.24448168 | F28: 0 | G28: =D28*F28/10000 -> 0 | H28: =G28/10000 -> 0 | I28: =H28*$P$30 -> 0 | J28: =E28+I28 -> 0.24448168 | M28: 双极纳米片 | N28: =在此导入!C7 -> 93.282046 | O28: 168 | P28: =N28*O28/10000 -> 1.5671384
B29: 手性屈光体 | C29: =在此导入!C9 -> 74.234875 | D29: 40 | E29: =C29*D29/10000 -> 0.2969395 | F29: 0 | G29: =D29*F29/10000 -> 0 | H29: =G29/10000 -> 0 | I29: =H29*$P$30 -> 0 | J29: =E29+I29 -> 0.2969395 | M29: 重相位对映体 | N29: =在此导入!C8 -> 304.11023 | O29: 168 | P29: =N29*O29/10000 -> 5.1090519
B30: 液化醚吸聚体 | C30: =在此导入!C10 -> 66.228899 | D30: 40 | E30: =C30*D30/10000 -> 0.2649156 | F30: 0 | G30: =D30*F30/10000 -> 0 | H30: =G30/10000 -> 0 | I30: =H30*$P$30 -> 0 | J30: =E30+I30 -> 0.2649156 | L30: 总计 | O30: =SUM(O3:O29) -> 10000 | P30: =SUM(P3:P29) -> 78.380085 | R30: =P30/E47 -> 3.9541749
B31: 聚能动力单元 | C31: =在此导入!C11 -> 84.970473 | D31: 40 | E31: =C31*D31/10000 -> 0.33988189 | F31: 0 | G31: =D31*F31/10000 -> 0 | H31: =G31/10000 -> 0 | I31: =H31*$P$30 -> 0 | J31: =E31+I31 -> 0.33988189
B32: 异铁块 | C32: =在此导入!C12 -> 95.513345 | D32: 40 | E32: =C32*D32/10000 -> 0.38205338 | F32: 0 | G32: =D32*F32/10000 -> 0 | H32: =G32/10000 -> 0 | I32: =H32*$P$30 -> 0 | J32: =E32+I32 -> 0.38205338
B33: 环烃预制体 | C33: =在此导入!C13 -> 87.081846 | D33: 40 | E33: =C33*D33/10000 -> 0.34832738 | F33: 0 | G33: =D33*F33/10000 -> 0 | H33: =G33/10000 -> 0 | I33: =H33*$P$30 -> 0 | J33: =E33+I33 -> 0.34832738
B34: 酮阵列 | C34: =在此导入!C14 -> 65.802333 | D34: 40 | E34: =C34*D34/10000 -> 0.26320933 | F34: 0 | G34: =D34*F34/10000 -> 0 | H34: =G34/10000 -> 0 | I34: =H34*$P$30 -> 0 | J34: =E34+I34 -> 0.26320933
B35: 改量装置 | C35: =在此导入!C15 -> 63.342877 | D35: 40 | E35: =C35*D35/10000 -> 0.25337151 | F35: 0 | G35: =D35*F35/10000 -> 0 | H35: =G35/10000 -> 0 | I35: =H35*$P$30 -> 0 | J35: =E35+I35 -> 0.25337151
B36: RMA70-24 | C36: =在此导入!C16 -> 55.702369 | D36: 40 | E36: =C36*D36/10000 -> 0.22280947 | F36: 0 | G36: =D36*F36/10000 -> 0 | H36: =G36/10000 -> 0 | I36: =H36*$P$30 -> 0 | J36: =E36+I36 -> 0.22280947
B37: 五水研磨石 | C37: =在此导入!C17 -> 55.044825 | D37: 40 | E37: =C37*D37/10000 -> 0.2201793 | F37: 0 | G37: =D37*F37/10000 -> 0 | H37: =G37/10000 -> 0 | I37: =H37*$P$30 -> 0 | J37: =E37+I37 -> 0.2201793
B38: 固化纤维板 | C38: =在此导入!C18 -> 79.78212 | D38: 40 | E38: =C38*D38/10000 -> 0.31912848 | F38: 0 | G38: =D38*F38/10000 -> 0 | H38: =G38/10000 -> 0 | I38: =H38*$P$30 -> 0 | J38: =E38+I38 -> 0.31912848
B39: 晶体电路 | C39: =在此导入!C20 -> 76.005608 | D39: 40 | E39: =C39*D39/10000 -> 0.30402243 | F39: 0 | G39: =D39*F39/10000 -> 0 | H39: =G39/10000 -> 0 | I39: =H39*$P$30 -> 0 | J39: =E39+I39 -> 0.30402243
B40: 炽合金块 | C40: =在此导入!C21 -> 53.480204 | D40: 40 | E40: =C40*D40/10000 -> 0.21392081 | F40: 0 | G40: =D40*F40/10000 -> 0 | H40: =G40/10000 -> 0 | I40: =H40*$P$30 -> 0 | J40: =E40+I40 -> 0.21392081
...

Sheet 计算表 (2)
A1: 回收站池子1权重 | L1: 回收站池子2权重
A2: 绿材料 | B2: 材料名 | C2: 理智价值 | D2: 权重 | E2: 理智 | F2: 积分 | G2: 期望积分 | H2: 池子2摸奖次数 | I2: 池子2摸奖理智 | J2: 总理智 | M2: 材料名 | N2: 理智价值 | O2: 权重 | P2: 理智
B3: 装置 | C3: =在此导入!C51 -> 8.142283 | D3: 717 | E3: =C3*D3/10000 -> 0.58380169 | F3: 650 | G3: =D3*F3/10000 -> 46.605 | H3: =G3/10526.13 -> 0.0044275531 | I3: =H3*($P$30-$E$47) -> 0.25926855 | J3: =E3+I3 -> 0.84307024 | L3: 单独2种紫材料 | M3: 聚酸酯块 | N3: =C9 -> 60.689845 | O3: 40 | P3: =N3*O3/10000 -> 0.24275938
B4: 酮凝集 | C4: =在此导入!C52 -> 6.142156 | D4: 717 | E4: =C4*D4/10000 -> 0.44039259 | F4: 650 | G4: =D4*F4/10000 -> 46.605 | H4: =G4/10526.13 -> 0.0044275531 | I4: =H4*($P$30-$E$47) -> 0.25926855 | J4: =E4+I4 -> 0.69966114 | M4: 糖聚块 | N4: =C10 -> 61.049845 | O4: 40 | P4: =N4*O4/10000 -> 0.24419938
B5: 异铁 | C5: =在此导入!C53 -> 6.142156 | D5: 717 | E5: =C5*D5/10000 -> 0.44039259 | F5: 650 | G5: =D5*F5/10000 -> 46.605 | H5: =G5/10526.13 -> 0.0044275531 | I5: =H5*($P$30-$E$47) -> 0.25926855 | J5: =E5+I5 -> 0.69966114 | L5: 单独紫土 | M5: 提纯源岩 | N5: =C28 -> 61.120421 | O5: 488 | P5: =N5*O5/10000 -> 2.9826765
B6: 聚酸酯 | C6: =在此导入!C54 -> 4.954034 | D6: 717 | E6: =C6*D6/10000 -> 0.35520424 | F6: 650 | G6: =D6*F6/10000 -> 46.605 | H6: =G6/10526.13 -> 0.0044275531 | I6: =H6*($P$30-$E$47) -> 0.25926855 | J6: =E6+I6 -> 0.61447279 | L6: 其余紫材料 | M6: 手性屈光体 | N6: =C29 -> 74.234875 | O6: 468 | P6: =N6*O6/10000 -> 3.4741921
B7: 糖 | C7: =在此导入!C55 -> 4.954034 | D7: 717 | E7: =C7*D7/10000 -> 0.35520424 | F7: 650 | G7: =D7*F7/10000 -> 46.605 | H7: =G7/10526.13 -> 0.0044275531 | I7: =H7*($P$30-$E$47) -> 0.25926855 | J7: =E7+I7 -> 0.61447279 | M7: 液化醚吸聚体 | N7: =C30 -> 66.228899 | O7: 468 | P7: =N7*O7/10000 -> 3.0995125
B8: 固源岩 | C8: =在此导入!C56 -> 3.35648 | D8: 717 | E8: =C8*D8/10000 -> 0.24065962 | F8: 650 | G8: =D8*F8/10000 -> 46.605 | H8: =G8/10526.13 -> 0.0044275531 | I8: =H8*($P$30-$E$47) -> 0.25926855 | J8: =E8+I8 -> 0.49992817 | M8: 聚能动力单元 | N8: =C31 -> 84.970473 | O8: 468 | P8: =N8*O8/10000 -> 3.9766181
A9: 单独2种紫材料 | B9: 聚酸酯块 | C9: =在此导入!C27 -> 60.689845 | D9: 4 | E9: =C9*D9/10000 -> 0.024275938 | F9: 0 | G9: =D9*F9/10000 -> 0 | H9: =G9/10526.13 -> 0 | I9: =H9*($P$30-$E$47) -> 0 | J9: =E9+I9 -> 0.024275938 | M9: 异铁块 | N9: =C32 -> 95.513345 | O9: 468 | P9: =N9*O9/10000 -> 4.4700245
B10: 糖聚块 | C10: =在此导入!C19 -> 61.049845 | D10: 4 | E10: =C10*D10/10000 -> 0.024419938 | F10: 0 | G10: =D10*F10/10000 -> 0 | H10: =G10/10526.13 -> 0 | I10: =H10*($P$30-$E$47) -> 0 | J10: =E10+I10 -> 0.024419938 | M10: 环烃预制体 | N10: =C33 -> 87.081846 | O10: 468 | P10: =N10*O10/10000 -> 4.0754304
A11: 蓝材料(不含4中坚) | B11: 环烃聚质 | C11: =在此导入!C30 -> 31.87648 | D11: 290 | E11: =C11*D11/10000 -> 0.92441791 | F11: 500 | G11: =D11*F11/10000 -> 14.5 | H11: =G11/10526.13 -> 0.0013775243 | I11: =H11*($P$30-$E$47) -> 0.080665036 | J11: =E11+I11 -> 1.0050829 | M11: 酮阵列 | N11: =C34 -> 65.802333 | O11: 468 | P11: =N11*O11/10000 -> 3.0795492
B12: 类凝结核 | C12: =在此导入!C31 -> 26.45707 | D12: 290 | E12: =C12*D12/10000 -> 0.76725502 | F12: 500 | G12: =D12*F12/10000 -> 14.5 | H12: =G12/10526.13 -> 0.0013775243 | I12: =H12*($P$30-$E$47) -> 0.080665036 | J12: =E12+I12 -> 0.84792005 | M12: 改量装置 | N12: =C35 -> 63.342877 | O12: 468 | P12: =N12*O12/10000 -> 2.9644466
B13: 液化高能气体 | C13: =在此导入!C32 -> 29.772152 | D13: 290 | E13: =C13*D13/10000 -> 0.86339241 | F13: 500 | G13: =D13*F13/10000 -> 14.5 | H13: =G13/10526.13 -> 0.0013775243 | I13: =H13*($P$30-$E$47) -> 0.080665036 | J13: =E13+I13 -> 0.94405744 | M13: RMA70-24 | N13: =C36 -> 55.702369 | O13: 468 | P13: =N13*O13/10000 -> 2.6068709
B14: 电极单元 | C14: =在此导入!C33 -> 26.544 | D14: 290 | E14: =C14*D14/10000 -> 0.769776 | F14: 500 | G14: =D14*F14/10000 -> 14.5 | H14: =G14/10526.13 -> 0.0013775243 | I14: =H14*($P$30-$E$47) -> 0.080665036 | J14: =E14+I14 -> 0.85044104 | M14: 五水研磨石 | N14: =C37 -> 55.044825 | O14: 468 | P14: =N14*O14/10000 -> 2.5760978
B15: 全新装置 | C15: =在此导入!C34 -> 31.871012 | D15: 290 | E15: =C15*D15/10000 -> 0.92425935 | F15: 500 | G15: =D15*F15/10000 -> 14.5 | H15: =G15/10526.13 -> 0.0013775243 | I15: =H15*($P$30-$E$47) -> 0.080665036 | J15: =E15+I15 -> 1.0049244 | M15: 固化纤维板 | N15: =C38 -> 79.78212 | O15: 468 | P15: =N15*O15/10000 -> 3.7338032
B16: 褐素纤维 | C16: =在此导入!C36 -> 28.6785 | D16: 290 | E16: =C16*D16/10000 -> 0.83167649 | F16: 500 | G16: =D16*F16/10000 -> 14.5 | H16: =G16/10526.13 -> 0.0013775243 | I16: =H16*($P$30-$E$47) -> 0.080665036 | J16: =E16+I16 -> 0.91234153 | M16: 晶体电路 | N16: =C39 -> 76.005608 | O16: 468 | P16: =N16*O16/10000 -> 3.5570624
B17: 转质盐组 | C17: =在此导入!C37 -> 29.743557 | D17: 290 | E17: =C17*D17/10000 -> 0.86256315 | F17: 500 | G17: =D17*F17/10000 -> 14.5 | H17: =G17/10526.13 -> 0.0013775243 | I17: =H17*($P$30-$E$47) -> 0.080665036 | J17: =E17+I17 -> 0.94322819 | M17: 炽合金块 | N17: =C40 -> 53.480204 | O17: 468 | P17: =N17*O17/10000 -> 2.5028735
B18: 化合切削液 | C18: =在此导入!C39 -> 26.453303 | D18: 290 | E18: =C18*D18/10000 -> 0.76714579 | F18: 500 | G18: =D18*F18/10000 -> 14.5 | H18: =G18/10526.13 -> 0.0013775243 | I18: =H18*($P$30-$E$47) -> 0.080665036 | J18: =E18+I18 -> 0.84781082 | M18: 精炼溶剂 | N18: =C41 -> 74.158288 | O18: 468 | P18: =N18*O18/10000 -> 3.4706079
B19: 凝胶 | C19: =在此导入!C40 -> 24.45707 | D19: 290 | E19: =C19*D19/10000 -> 0.70925502 | F19: 500 | G19: =D19*F19/10000 -> 14.5 | H19: =G19/10526.13 -> 0.0013775243 | I19: =H19*($P$30-$E$47) -> 0.080665036 | J19: =E19+I19 -> 0.78992005 | M19: 切削原液 | N19: =C42 -> 49.683406 | O19: 468 | P19: =N19*O19/10000 -> 2.3251834
B20: 半自然溶剂 | C20: =在此导入!C41 -> 26.464606 | D20: 290 | E20: =C20*D20/10000 -> 0.76747358 | F20: 500 | G20: =D20*F20/10000 -> 14.5 | H20: =G20/10526.13 -> 0.0013775243 | I20: =H20*($P$30-$E$47) -> 0.080665036 | J20: =E20+I20 -> 0.84813861 | M20: 转质盐聚块 | N20: =C43 -> 72.109489 | O20: 468 | P20: =N20*O20/10000 -> 3.3747241
B21: 酮凝集组 | C21: =在此导入!C43 -> 23.870504 | D21: 290 | E21: =C21*D21/10000 -> 0.6922446 | F21: 500 | G21: =D21*F21/10000 -> 14.5 | H21: =G21/10526.13 -> 0.0013775243 | I21: =H21*($P$30-$E$47) -> 0.080665036 | J21: =E21+I21 -> 0.77290964 | M21: 聚合凝胶 | N21: =C44 -> 62.525351 | O21: 468 | P21: =N21*O21/10000 -> 2.9261864
B22: 异铁组 | C22: =在此导入!C44 -> 23.870504 | D22: 290 | E22: =C22*D22/10000 -> 0.6922446 | F22: 500 | G22: =D22*F22/10000 -> 14.5 | H22: =G22/10526.13 -> 0.0013775243 | I22: =H22*($P$30-$E$47) -> 0.080665036 | J22: =E22+I22 -> 0.77290964 | M22: 三水锰矿 | N22: =C45 -> 22.021326 | O22: 468 | P22: =N22*O22/10000 -> 1.030598
B23: 炽合金 | C23: =在此导入!C46 -> 22.305882 | D23: 290 | E23: =C23*D23/10000 -> 0.64687059 | F23: 500 | G23: =D23*F23/10000 -> 14.5 | H23: =G23/10526.13 -> 0.0013775243 | I23: =H23*($P$30-$E$47) -> 0.080665036 | J23: =E23+I23 -> 0.72753562 | M23: 白马醇 | N23: =C46 -> 20.581326 | O23: 468 | P23: =N23*O23/10000 -> 0.96320604
B24: 聚酸酯组 | C24: =在此导入!C47 -> 19.118016 | D24: 290 | E24: =C24*D24/10000 -> 0.55442247 | F24: 500 | G24: =D24*F24/10000 -> 14.5 | H24: =G24/10526.13 -> 0.0013775243 | I24: =H24*($P$30-$E$47) -> 0.080665036 | J24: =E24+I24 -> 0.63508751 | L24: 金材料 | M24: 晶体电子单元 | N24: =在此导入!C3 -> 243.31303 | O24: 168 | P24: =N24*O24/10000 -> 4.0876589
B25: 糖组 | C25: =在此导入!C48 -> 19.118016 | D25: 290 | E25: =C25*D25/10000 -> 0.55442247 | F25: 500 | G25: =D25*F25/10000 -> 14.5 | H25: =G25/10526.13 -> 0.0013775243 | I25: =H25*($P$30-$E$47) -> 0.080665036 | J25: =E25+I25 -> 0.63508751 | M25: 烧结核凝晶 | N25: =在此导入!C4 -> 258.88599 | O25: 168 | P25: =N25*O25/10000 -> 4.3492846
B26: 晶体元件 | C26: =在此导入!C49 -> 23.666794 | D26: 290 | E26: =C26*D26/10000 -> 0.68633703 | F26: 500 | G26: =D26*F26/10000 -> 14.5 | H26: =G26/10526.13 -> 0.0013775243 | I26: =H26*($P$30-$E$47) -> 0.080665036 | J26: =E26+I26 -> 0.76700206 | M26: 聚合剂 | N26: =在此导入!C5 -> 211.21262 | O26: 168 | P26: =N26*O26/10000 -> 3.548372
B27: 固源岩组 | C27: =在此导入!C50 -> 16.084278 | D27: 290 | E27: =C27*D27/10000 -> 0.46644406 | F27: 500 | G27: =D27*F27/10000 -> 14.5 | H27: =G27/10526.13 -> 0.0013775243 | I27: =H27*($P$30-$E$47) -> 0.080665036 | J27: =E27+I27 -> 0.54710909 | M27: D32钢 | N27: =在此导入!C6 -> 121.54504 | O27: 168 | P27: =N27*O27/10000 -> 2.0419566
A28: 其余紫材料 | B28: 提纯源岩 | C28: =在此导入!C28 -> 61.120421 | D28: 40 | E28: =C28*D28/10000 -> 0.24448168 | F28: 0 | G28: =D28*F28/10000 -> 0 | H28: =G28/10526.13 -> 0 | I28: =H28*($P$30-$E$47) -> 0 | J28: =E28+I28 -> 0.24448168 | M28: 双极纳米片 | N28: =在此导入!C7 -> 93.282046 | O28: 168 | P28: =N28*O28/10000 -> 1.5671384
B29: 手性屈光体 | C29: =在此导入!C9 -> 74.234875 | D29: 40 | E29: =C29*D29/10000 -> 0.2969395 | F29: 0 | G29: =D29*F29/10000 -> 0 | H29: =G29/10526.13 -> 0 | I29: =H29*($P$30-$E$47) -> 0 | J29: =E29+I29 -> 0.2969395 | M29: 重相位对映体 | N29: =在此导入!C8 -> 304.11023 | O29: 168 | P29: =N29*O29/10000 -> 5.1090519
B30: 液化醚吸聚体 | C30: =在此导入!C10 -> 66.228899 | D30: 40 | E30: =C30*D30/10000 -> 0.2649156 | F30: 0 | G30: =D30*F30/10000 -> 0 | H30: =G30/10526.13 -> 0 | I30: =H30*($P$30-$E$47) -> 0 | J30: =E30+I30 -> 0.2649156 | L30: 总计 | O30: =SUM(O3:O29) -> 10000 | P30: =SUM(P3:P29) -> 78.380085 | R30: =P30/E47 -> 3.9541749
B31: 聚能动力单元 | C31: =在此导入!C11 -> 84.970473 | D31: 40 | E31: =C31*D31/10000 -> 0.33988189 | F31: 0 | G31: =D31*F31/10000 -> 0 | H31: =G31/10526.13 -> 0 | I31: =H31*($P$30-$E$47) -> 0 | J31: =E31+I31 -> 0.33988189
B32: 异铁块 | C32: =在此导入!C12 -> 95.513345 | D32: 40 | E32: =C32*D32/10000 -> 0.38205338 | F32: 0 | G32: =D32*F32/10000 -> 0 | H32: =G32/10526.13 -> 0 | I32: =H32*($P$30-$E$47) -> 0 | J32: =E32+I32 -> 0.38205338
B33: 环烃预制体 | C33: =在此导入!C13 -> 87.081846 | D33: 40 | E33: =C33*D33/10000 -> 0.34832738 | F33: 0 | G33: =D33*F33/10000 -> 0 | H33: =G33/10526.13 -> 0 | I33: =H33*($P$30-$E$47) -> 0 | J33: =E33+I33 -> 0.34832738
B34: 酮阵列 | C34: =在此导入!C14 -> 65.802333 | D34: 40 | E34: =C34*D34/10000 -> 0.26320933 | F34: 0 | G34: =D34*F34/10000 -> 0 | H34: =G34/10526.13 -> 0 | I34: =H34*($P$30-$E$47) -> 0 | J34: =E34+I34 -> 0.26320933
B35: 改量装置 | C35: =在此导入!C15 -> 63.342877 | D35: 40 | E35: =C35*D35/10000 -> 0.25337151 | F35: 0 | G35: =D35*F35/10000 -> 0 | H35: =G35/10526.13 -> 0 | I35: =H35*($P$30-$E$47) -> 0 | J35: =E35+I35 -> 0.25337151
B36: RMA70-24 | C36: =在此导入!C16 -> 55.702369 | D36: 40 | E36: =C36*D36/10000 -> 0.22280947 | F36: 0 | G36: =D36*F36/10000 -> 0 | H36: =G36/10526.13 -> 0 | I36: =H36*($P$30-$E$47) -> 0 | J36: =E36+I36 -> 0.22280947
B37: 五水研磨石 | C37: =在此导入!C17 -> 55.044825 | D37: 40 | E37: =C37*D37/10000 -> 0.2201793 | F37: 0 | G37: =D37*F37/10000 -> 0 | H37: =G37/10526.13 -> 0 | I37: =H37*($P$30-$E$47) -> 0 | J37: =E37+I37 -> 0.2201793
B38: 固化纤维板 | C38: =在此导入!C18 -> 79.78212 | D38: 40 | E38: =C38*D38/10000 -> 0.31912848 | F38: 0 | G38: =D38*F38/10000 -> 0 | H38: =G38/10526.13 -> 0 | I38: =H38*($P$30-$E$47) -> 0 | J38: =E38+I38 -> 0.31912848
B39: 晶体电路 | C39: =在此导入!C20 -> 76.005608 | D39: 40 | E39: =C39*D39/10000 -> 0.30402243 | F39: 0 | G39: =D39*F39/10000 -> 0 | H39: =G39/10526.13 -> 0 | I39: =H39*($P$30-$E$47) -> 0 | J39: =E39+I39 -> 0.30402243
B40: 炽合金块 | C40: =在此导入!C21 -> 53.480204 | D40: 40 | E40: =C40*D40/10000 -> 0.21392081 | F40: 0 | G40: =D40*F40/10000 -> 0 | H40: =G40/10526.13 -> 0 | I40: =H40*($P$30-$E$47) -> 0 | J40: =E40+I40 -> 0.21392081
...
